Workbook

Sheet Sheet1
A1: Technical Name | B1: NoDataAsZero | C1: Cube | D1: Entity | E1: Parent | F1: Cons | G1: Scenario | H1: Time | I1: View | J1: Account | K1: Flow | L1: Origin | M1: IC | N1: UD1 | O1: UD2 | P1: UD3 | Q1: UD4 | R1: UD5 | S1: UD6 | T1: UD7 | U1: UD8
A2: What I'd call it | D2: Company | F2: consolidation | G2: actual/forecast/budget | J2: Account | N2: Department | O2: company_department | P2: Facility | Q2: Activity | R2: Other
A3: example 1 | B3: TRUE | C3: FinReporting | D3: 111 | F3: USD | G3: Actual | H3: 2026M01 | I3: Periodic | J3: 606050 | K3: EndBalLoad | L3: Top | M3: Top | N3: 170 | O3: 111_170 | P3: Top | Q3: Top | R3: Top | S3: Top | T3: Top | U3: Top | V3: =_xll.OneStreamExcelAddIn.XFFunctions.XFGetCell(B3,C3,D3,E3,F3,G3,H3,I3,J3,K3,L3,M3,N3,O3,P3,Q3,R3,S3,T3,U3) -> 50397
A4: example 2 | B4: TRUE | C4: FinReporting | D4: DSH | F4: USD | G4: Actual | H4: 2026M1 | I4: MTD | J4: S10181 | K4: BegBalCalc | L4: Top | M4: Top | N4: Top | O4: DTV_BBH | P4: Top | Q4: Top | R4: Top | S4: Top | T4: Top | U4: None | V4: =_xll.OneStreamExcelAddIn.XFFunctions.XFGetCell(B4,C4,D4,E4,F4,G4,H4,I4,J4,K4,L4,M4,N4,O4,P4,Q4,R4,S4,T4,U4) -> 5021607
B13: TRUE | C13: finreporting | D13: 113 | F13: USD | G13: Actual | H13: =INDEX('User Inputs'!$G$3:$G$14,MATCH(1,'User Inputs'!$J$3:$J$14,0)) -> 2026M05 | I13: Periodic | J13: SUBAAD | K13: EndBal | L13: Top | M13: None | N13: 100 | O13: =_xlfn.CONCAT(D13,"_",N13) -> 113_100 | P13: Top | Q13: Top | R13: Top | S13: Top | T13: Top | U13: Top | V13: =_xll.OneStreamExcelAddIn.XFFunctions.XFGetCell(B13,C13,D13,E13,F13,G13,H13,I13,J13,K13,L13,M13,N13,O13,P13,Q13,R13,S13,T13,U13) -> 171948.07
B24: not completed because of the SACADV stuff!!!
A38: 113-100SUBAAD | D38: =LEFT(A38,3) -> 113 | N38: =MID(A38,5,3) -> 100
A39: 113-101SUBAAD | D39: =LEFT(A39,3) -> 113 | N39: =MID(A39,5,3) -> 101
A40: 113-102SUBAAD | D40: =LEFT(A40,3) -> 113 | N40: =MID(A40,5,3) -> 102
A41: 113-103SUBAAD | D41: =LEFT(A41,3) -> 113 | N41: =MID(A41,5,3) -> 103
A42: 113-120SUBAAD | D42: =LEFT(A42,3) -> 113 | N42: =MID(A42,5,3) -> 120
A43: 113-125SUBAAD | D43: =LEFT(A43,3) -> 113 | N43: =MID(A43,5,3) -> 125
A44: 113-130SUBAAD | D44: =LEFT(A44,3) -> 113 | N44: =MID(A44,5,3) -> 130
A45: 113-131SUBAAD | D45: =LEFT(A45,3) -> 113 | N45: =MID(A45,5,3) -> 131
A46: 113-135SUBAAD | D46: =LEFT(A46,3) -> 113 | N46: =MID(A46,5,3) -> 135
A47: 113-115SUBAAD | D47: =LEFT(A47,3) -> 113 | N47: =MID(A47,5,3) -> 115
A48: 113-132SUBAAD | D48: =LEFT(A48,3) -> 113 | N48: =MID(A48,5,3) -> 132
A49: 111-443SUBAAD | D49: =LEFT(A49,3) -> 111 | N49: =MID(A49,5,3) -> 443
... A63: 111-170SACADV000000 | D63: =LEFT(A63,3) -> 111 | N63: =MID(A63,5,3) -> 170
D64: =LEFT(A64,3) | N64: =MID(A64,5,3)
A65: 186-520SUBAAD | D65: =LEFT(A65,3) -> 186 | N65: =MID(A65,5,3) -> 520
A66: 111-380SUBAAD | D66: =LEFT(A66,3) -> 111 | N66: =MID(A66,5,3) -> 380
A67: 290-380SUBAAD | D67: =LEFT(A67,3) -> 290 | N67: =MID(A67,5,3) -> 380
A68: 111-105SUBAAD | D68: =LEFT(A68,3) -> 111 | N68: =MID(A68,5,3) -> 105
A69: 111-304SUBAAD | D69: =LEFT(A69,3) -> 111 | N69: =MID(A69,5,3) -> 304
A70: 113-501SUBAAD | D70: =LEFT(A70,3) -> 113 | N70: =MID(A70,5,3) -> 501
A71: 113-500SUBAAD | D71: =LEFT(A71,3) -> 113 | N71: =MID(A71,5,3) -> 500
A72: 113-525SUBAAD | D72: =LEFT(A72,3) -> 113 | N72: =MID(A72,5,3) -> 525
A73: IT-113 SUBAAD | D73: =LEFT(A73,3) -> IT- | N73: =MID(A73,5,3) -> 13
A74: 111-170SACADV000002 | D74: =LEFT(A74,3) -> 111 | N74: =MID(A74,5,3) -> 170
D75: =LEFT(A75,3) | N75: =MID(A75,5,3)
A76: 113-110SUBAAD | D76: =LEFT(A76,3) -> 113 | N76: =MID(A76,5,3) -> 110
A77: 111-175SUBAAD | D77: =LEFT(A77,3) -> 111 | N77: =MID(A77,5,3) -> 175
A78: 113-513SUBAAD | D78: =LEFT(A78,3) -> 113 | N78: =MID(A78,5,3) -> 513
A79: 113-519SUBAAD | D79: =LEFT(A79,3) -> 113 | N79: =MID(A79,5,3) -> 519
A80: 113-515SUBAAD | D80: =LEFT(A80,3) -> 113 | N80: =MID(A80,5,3) -> 515
A81: 113-510SUBAAD | D81: =LEFT(A81,3) -> 113 | N81: =MID(A81,5,3) -> 510
A82: 113-518SUBAAD | D82: =LEFT(A82,3) -> 113 | N82: =MID(A82,5,3) -> 518
A83: 111-307SUBAAD | D83: =LEFT(A83,3) -> 111 | N83: =MID(A83,5,3) -> 307
A84: 113-517SUBAAD | D84: =LEFT(A84,3) -> 113 | N84: =MID(A84,5,3) -> 517
...

Sheet User Inputs
B2: What Month is it?
B3: Use the Dropdown Menu Below | G3: =_xlfn.CONCAT($B$8,"M",H3) -> 2026M01 | H3: 01 | I3: January | J3: =IF($B$4=I3,1,0) -> 0
B4: May | G4: =_xlfn.CONCAT($B$8,"M",H4) -> 2026M02 | H4: 02 | I4: February | J4: =IF($B$4=I4,1,0) -> 0
G5: =_xlfn.CONCAT($B$8,"M",H5) -> 2026M03 | H5: 03 | I5: March | J5: =IF($B$4=I5,1,0) -> 0
B6: What Year is it? | G6: =_xlfn.CONCAT($B$8,"M",H6) -> 2026M04 | H6: 04 | I6: April | J6: =IF($B$4=I6,1,0) -> 0
B7: type it in Below: | G7: =_xlfn.CONCAT($B$8,"M",H7) -> 2026M05 | H7: 05 | I7: May | J7: =IF($B$4=I7,1,0) -> 1
B8: 2026 | G8: =_xlfn.CONCAT($B$8,"M",H8) -> 2026M06 | H8: 06 | I8: June | J8: =IF($B$4=I8,1,0) -> 0
G9: =_xlfn.CONCAT($B$8,"M",H9) -> 2026M07 | H9: 07 | I9: July | J9: =IF($B$4=I9,1,0) -> 0
G10: =_xlfn.CONCAT($B$8,"M",H10) -> 2026M08 | H10: 08 | I10: August | J10: =IF($B$4=I10,1,0) -> 0
G11: =_xlfn.CONCAT($B$8,"M",H11) -> 2026M09 | H11: 09 | I11: September | J11: =IF($B$4=I11,1,0) -> 0
G12: =_xlfn.CONCAT($B$8,"M",H12) -> 2026M10 | H12: 10 | I12: October | J12: =IF($B$4=I12,1,0) -> 0
G13: =_xlfn.CONCAT($B$8,"M",H13) -> 2026M11 | H13: 11 | I13: November | J13: =IF($B$4=I13,1,0) -> 0
G14: =_xlfn.CONCAT($B$8,"M",H14) -> 2026M12 | H14: 12 | I14: December | J14: =IF($B$4=I14,1,0) -> 0

Sheet OneStream Pulls
A1: NoDataToZero | B1: Cube | C1: Entity | D1: Parent | E1: Cons | F1: Scenario | G1: Time | H1: View | I1: Account | J1: Flow | K1: Origin | L1: IC | M1: UD1 | N1: UD2 | O1: UD3 | P1: UD4 | Q1: UD5 | R1: UD6 | S1: UD7 | T1: UD8 | U1: Data
A2: TRUE | B2: finreporting | C2: 111 | E2: USD | F2: Actual | G2: =INDEX('User Inputs'!$G$3:$G$14,MATCH(1,'User Inputs'!$J$3:$J$14,0)) -> 2026M05 | H2: Periodic | I2: 611000 | J2: EndBal | K2: Top | L2: None | M2: 170 | N2: =_xlfn.CONCAT(C2,"_",M2) -> 111_170 | O2: Top | P2: 330130 | Q2: Top | R2: Top | S2: Top | T2: Top | U2: =_xll.OneStreamExcelAddIn.XFFunctions.XFGetCell(A2,B2,C2,D2,E2,F2,G2,H2,I2,J2,K2,L2,M2,N2,O2,P2,Q2,R2,S2,T2) -> 0
A3: TRUE | B3: finreporting | C3: 111 | E3: USD | F3: Actual | G3: =INDEX('User Inputs'!$G$3:$G$14,MATCH(1,'User Inputs'!$J$3:$J$14,0)) -> 2026M05 | H3: Periodic | I3: 611000 | J3: EndBal | K3: Top | L3: None | M3: 170 | N3: =_xlfn.CONCAT(C3,"_",M3) -> 111_170 | O3: Top | P3: 330160 | Q3: Top | R3: Top | S3: Top | T3: Top | U3: =_xll.OneStreamExcelAddIn.XFFunctions.XFGetCell(A3,B3,C3,D3,E3,F3,G3,H3,I3,J3,K3,L3,M3,N3,O3,P3,Q3,R3,S3,T3) -> 0
A4: TRUE | B4: finreporting | C4: 111 | E4: USD | F4: Actual | G4: =INDEX('User Inputs'!$G$3:$G$14,MATCH(1,'User Inputs'!$J$3:$J$14,0)) -> 2026M05 | H4: Periodic | I4: 611000 | J4: EndBal | K4: Top | L4: None | M4: 170 | N4: =_xlfn.CONCAT(C4,"_",M4) -> 111_170 | O4: Top | P4: 330170 | Q4: Top | R4: Top | S4: Top | T4: Top | U4: =_xll.OneStreamExcelAddIn.XFFunctions.XFGetCell(A4,B4,C4,D4,E4,F4,G4,H4,I4,J4,K4,L4,M4,N4,O4,P4,Q4,R4,S4,T4) -> 0
A5: TRUE | B5: finreporting | C5: 111 | E5: USD | F5: Actual | G5: =INDEX('User Inputs'!$G$3:$G$14,MATCH(1,'User Inputs'!$J$3:$J$14,0)) -> 2026M05 | H5: Periodic | I5: 611000 | J5: EndBal | K5: Top | L5: None | M5: 170 | N5: =_xlfn.CONCAT(C5,"_",M5) -> 111_170 | O5: Top | P5: 330120 | Q5: Top | R5: Top | S5: Top | T5: Top | U5: =_xll.OneStreamExcelAddIn.XFFunctions.XFGetCell(A5,B5,C5,D5,E5,F5,G5,H5,I5,J5,K5,L5,M5,N5,O5,P5,Q5,R5,S5,T5) -> 0
A6: TRUE | B6: finreporting | C6: 111 | E6: USD | F6: Actual | G6: =INDEX('User Inputs'!$G$3:$G$14,MATCH(1,'User Inputs'!$J$3:$J$14,0)) -> 2026M05 | H6: Periodic | I6: 611000 | J6: EndBal | K6: Top | L6: None | M6: 170 | N6: =_xlfn.CONCAT(C6,"_",M6) -> 111_170 | O6: Top | P6: 330100 | Q6: Top | R6: Top | S6: Top | T6: Top | U6: =_xll.OneStreamExcelAddIn.XFFunctions.XFGetCell(A6,B6,C6,D6,E6,F6,G6,H6,I6,J6,K6,L6,M6,N6,O6,P6,Q6,R6,S6,T6) -> 306779.49
A7: TRUE | B7: finreporting | C7: 111 | E7: USD | F7: Actual | G7: =INDEX('User Inputs'!$G$3:$G$14,MATCH(1,'User Inputs'!$J$3:$J$14,0)) -> 2026M05 | H7: Periodic | I7: 611000 | J7: EndBal | K7: Top | L7: None | M7: 170 | N7: =_xlfn.CONCAT(C7,"_",M7) -> 111_170 | O7: Top | P7: 330150 | Q7: Top | R7: Top | S7: Top | T7: Top | U7: =_xll.OneStreamExcelAddIn.XFFunctions.XFGetCell(A7,B7,C7,D7,E7,F7,G7,H7,I7,J7,K7,L7,M7,N7,O7,P7,Q7,R7,S7,T7) -> 0
A8: TRUE | B8: finreporting | C8: 111 | E8: USD | F8: Actual | G8: =INDEX('User Inputs'!$G$3:$G$14,MATCH(1,'User Inputs'!$J$3:$J$14,0)) -> 2026M05 | H8: Periodic | I8: 611000 | J8: EndBal | K8: Top | L8: None | M8: 170 | N8: =_xlfn.CONCAT(C8,"_",M8) -> 111_170 | O8: Top | P8: 330110 | Q8: Top | R8: Top | S8: Top | T8: Top | U8: =_xll.OneStreamExcelAddIn.XFFunctions.XFGetCell(A8,B8,C8,D8,E8,F8,G8,H8,I8,J8,K8,L8,M8,N8,O8,P8,Q8,R8,S8,T8) -> 0
A9: TRUE | B9: finreporting | C9: 111 | E9: USD | F9: Actual | G9: =INDEX('User Inputs'!$G$3:$G$14,MATCH(1,'User Inputs'!$J$3:$J$14,0)) -> 2026M05 | H9: Periodic | I9: 611000 | J9: EndBal | K9: Top | L9: None | M9: 170 | N9: =_xlfn.CONCAT(C9,"_",M9) -> 111_170 | O9: Top | P9: 330180 | Q9: Top | R9: Top | S9: Top | T9: Top | U9: =_xll.OneStreamExcelAddIn.XFFunctions.XFGetCell(A9,B9,C9,D9,E9,F9,G9,H9,I9,J9,K9,L9,M9,N9,O9,P9,Q9,R9,S9,T9) -> 0
A10: TRUE | B10: finreporting | C10: 111 | E10: USD | F10: Actual | G10: =INDEX('User Inputs'!$G$3:$G$14,MATCH(1,'User Inputs'!$J$3:$J$14,0)) -> 2026M05 | H10: Periodic | I10: 611000 | J10: EndBal | K10: Top | L10: None | M10: 170 | N10: =_xlfn.CONCAT(C10,"_",M10) -> 111_170 | O10: Top | P10: 331200 | Q10: Top | R10: Top | S10: Top | T10: Top | U10: =_xll.OneStreamExcelAddIn.XFFunctions.XFGetCell(A10,B10,C10,D10,E10,F10,G10,H10,I10,J10,K10,L10,M10,N10,O10,P10,Q10,R10,S10,T10) -> 35500
A11: TRUE | B11: finreporting | C11: 111 | E11: USD | F11: Actual | G11: =INDEX('User Inputs'!$G$3:$G$14,MATCH(1,'User Inputs'!$J$3:$J$14,0)) -> 2026M05 | H11: Periodic | I11: 611010 | J11: EndBal | K11: Top | L11: None | M11: 170 | N11: =_xlfn.CONCAT(C11,"_",M11) -> 111_170 | O11: Top | P11: 330210 | Q11: Top | R11: Top | S11: Top | T11: Top | U11: =_xll.OneStreamExcelAddIn.XFFunctions.XFGetCell(A11,B11,C11,D11,E11,F11,G11,H11,I11,J11,K11,L11,M11,N11,O11,P11,Q11,R11,S11,T11) -> 0
A12: TRUE | B12: finreporting | C12: 111 | E12: USD | F12: Actual | G12: =INDEX('User Inputs'!$G$3:$G$14,MATCH(1,'User Inputs'!$J$3:$J$14,0)) -> 2026M05 | H12: Periodic | I12: 611010 | J12: EndBal | K12: Top | L12: None | M12: 170 | N12: =_xlfn.CONCAT(C12,"_",M12) -> 111_170 | O12: Top | P12: 330200 | Q12: Top | R12: Top | S12: Top | T12: Top | U12: =_xll.OneStreamExcelAddIn.XFFunctions.XFGetCell(A12,B12,C12,D12,E12,F12,G12,H12,I12,J12,K12,L12,M12,N12,O12,P12,Q12,R12,S12,T12) -> 7977
A13: TRUE | B13: finreporting | C13: 111 | E13: USD | F13: Actual | G13: =INDEX('User Inputs'!$G$3:$G$14,MATCH(1,'User Inputs'!$J$3:$J$14,0)) -> 2026M05 | H13: Periodic | I13: 611010 | J13: EndBal | K13: Top | L13: None | M13: 170 | N13: =_xlfn.CONCAT(C13,"_",M13) -> 111_170 | O13: Top | P13: 330220 | Q13: Top | R13: Top | S13: Top | T13: Top | U13: =_xll.OneStreamExcelAddIn.XFFunctions.XFGetCell(A13,B13,C13,D13,E13,F13,G13,H13,I13,J13,K13,L13,M13,N13,O13,P13,Q13,R13,S13,T13) -> 0
... A58: TRUE | B58: finreporting | C58: 111 | E58: USD | F58: Actual | G58: =INDEX('User Inputs'!$G$3:$G$14,MATCH(1,'User Inputs'!$J$3:$J$14,0)) -> 2026M05 | H58: Periodic | I58: 618350 | J58: EndBal | K58: Top | L58: None | M58: 170 | N58: =_xlfn.CONCAT(C58,"_",M58) -> 111_170 | O58: Top | P58: 331300 | Q58: Top | R58: Top | S58: Top | T58: Top | U58: =_xll.OneStreamExcelAddIn.XFFunctions.XFGetCell(A58,B58,C58,D58,E58,F58,G58,H58,I58,J58,K58,L58,M58,N58,O58,P58,Q58,R58,S58,T58) -> 0
A59: TRUE | B59: finreporting | C59: 111 | E59: USD | F59: Actual | G59: =INDEX('User Inputs'!$G$3:$G$14,MATCH(1,'User Inputs'!$J$3:$J$14,0)) -> 2026M05 | H59: Periodic | I59: 626088 | J59: EndBal | K59: Top | L59: None | M59: 170 | N59: =_xlfn.CONCAT(C59,"_",M59) -> 111_170 | O59: Top | P59: Top | Q59: Top | R59: Top | S59: Top | T59: Top | U59: =_xll.OneStreamExcelAddIn.XFFunctions.XFGetCell(A59,B59,C59,D59,E59,F59,G59,H59,I59,J59,K59,L59,M59,N59,O59,P59,Q59,R59,S59,T59) -> 0
A60: TRUE | B60: finreporting | C60: 111 | E60: USD | F60: Actual | G60: =INDEX('User Inputs'!$G$3:$G$14,MATCH(1,'User Inputs'!$J$3:$J$14,0)) -> 2026M05 | H60: Periodic | I60: 629999 | J60: EndBal | K60: Top | L60: None | M60: 170 | N60: =_xlfn.CONCAT(C60,"_",M60) -> 111_170 | O60: Top | P60: 331100 | Q60: Top | R60: Top | S60: Top | T60: Top | U60: =_xll.OneStreamExcelAddIn.XFFunctions.XFGetCell(A60,B60,C60,D60,E60,F60,G60,H60,I60,J60,K60,L60,M60,N60,O60,P60,Q60,R60,S60,T60) -> 0
A61: TRUE | B61: finreporting | C61: 111 | E61: USD | F61: Actual | G61: =INDEX('User Inputs'!$G$3:$G$14,MATCH(1,'User Inputs'!$J$3:$J$14,0)) -> 2026M05 | H61: Periodic | I61: 611000 | J61: EndBal | K61: Top | L61: None | M61: 171 | N61: =_xlfn.CONCAT(C61,"_",M61) -> 111_171 | O61: Top | P61: 330130 | Q61: Top | R61: Top | S61: Top | T61: Top | U61: =_xll.OneStreamExcelAddIn.XFFunctions.XFGetCell(A61,B61,C61,D61,E61,F61,G61,H61,I61,J61,K61,L61,M61,N61,O61,P61,Q61,R61,S61,T61) -> 0
A62: TRUE | B62: finreporting | C62: 111 | E62: USD | F62: Actual | G62: =INDEX('User Inputs'!$G$3:$G$14,MATCH(1,'User Inputs'!$J$3:$J$14,0)) -> 2026M05 | H62: Periodic | I62: 611000 | J62: EndBal | K62: Top | L62: None | M62: 171 | N62: =_xlfn.CONCAT(C62,"_",M62) -> 111_171 | O62: Top | P62: 330160 | Q62: Top | R62: Top | S62: Top | T62: Top | U62: =_xll.OneStreamExcelAddIn.XFFunctions.XFGetCell(A62,B62,C62,D62,E62,F62,G62,H62,I62,J62,K62,L62,M62,N62,O62,P62,Q62,R62,S62,T62) -> 0
A63: TRUE | B63: finreporting | C63: 111 | E63: USD | F63: Actual | G63: =INDEX('User Inputs'!$G$3:$G$14,MATCH(1,'User Inputs'!$J$3:$J$14,0)) -> 2026M05 | H63: Periodic | I63: 611000 | J63: EndBal | K63: Top | L63: None | M63: 171 | N63: =_xlfn.CONCAT(C63,"_",M63) -> 111_171 | O63: Top | P63: 330170 | Q63: Top | R63: Top | S63: Top | T63: Top | U63: =_xll.OneStreamExcelAddIn.XFFunctions.XFGetCell(A63,B63,C63,D63,E63,F63,G63,H63,I63,J63,K63,L63,M63,N63,O63,P63,Q63,R63,S63,T63) -> 0
A64: TRUE | B64: finreporting | C64: 111 | E64: USD | F64: Actual | G64: =INDEX('User Inputs'!$G$3:$G$14,MATCH(1,'User Inputs'!$J$3:$J$14,0)) -> 2026M05 | H64: Periodic | I64: 611000 | J64: EndBal | K64: Top | L64: None | M64: 171 | N64: =_xlfn.CONCAT(C64,"_",M64) -> 111_171 | O64: Top | P64: 330120 | Q64: Top | R64: Top | S64: Top | T64: Top | U64: =_xll.OneStreamExcelAddIn.XFFunctions.XFGetCell(A64,B64,C64,D64,E64,F64,G64,H64,I64,J64,K64,L64,M64,N64,O64,P64,Q64,R64,S64,T64) -> 0
A65: TRUE | B65: finreporting | C65: 111 | E65: USD | F65: Actual | G65: =INDEX('User Inputs'!$G$3:$G$14,MATCH(1,'User Inputs'!$J$3:$J$14,0)) -> 2026M05 | H65: Periodic | I65: 611000 | J65: EndBal | K65: Top | L65: None | M65: 171 | N65: =_xlfn.CONCAT(C65,"_",M65) -> 111_171 | O65: Top | P65: 330100 | Q65: Top | R65: Top | S65: Top | T65: Top | U65: =_xll.OneStreamExcelAddIn.XFFunctions.XFGetCell(A65,B65,C65,D65,E65,F65,G65,H65,I65,J65,K65,L65,M65,N65,O65,P65,Q65,R65,S65,T65) -> 0
A66: TRUE | B66: finreporting | C66: 111 | E66: USD | F66: Actual | G66: =INDEX('User Inputs'!$G$3:$G$14,MATCH(1,'User Inputs'!$J$3:$J$14,0)) -> 2026M05 | H66: Periodic | I66: 611000 | J66: EndBal | K66: Top | L66: None | M66: 171 | N66: =_xlfn.CONCAT(C66,"_",M66) -> 111_171 | O66: Top | P66: 330150 | Q66: Top | R66: Top | S66: Top | T66: Top | U66: =_xll.OneStreamExcelAddIn.XFFunctions.XFGetCell(A66,B66,C66,D66,E66,F66,G66,H66,I66,J66,K66,L66,M66,N66,O66,P66,Q66,R66,S66,T66) -> 0
A67: TRUE | B67: finreporting | C67: 111 | E67: USD | F67: Actual | G67: =INDEX('User Inputs'!$G$3:$G$14,MATCH(1,'User Inputs'!$J$3:$J$14,0)) -> 2026M05 | H67: Periodic | I67: 611000 | J67: EndBal | K67: Top | L67: None | M67: 171 | N67: =_xlfn.CONCAT(C67,"_",M67) -> 111_171 | O67: Top | P67: 330110 | Q67: Top | R67: Top | S67: Top | T67: Top | U67: =_xll.OneStreamExcelAddIn.XFFunctions.XFGetCell(A67,B67,C67,D67,E67,F67,G67,H67,I67,J67,K67,L67,M67,N67,O67,P67,Q67,R67,S67,T67) -> 0
A68: TRUE | B68: finreporting | C68: 111 | E68: USD | F68: Actual | G68: =INDEX('User Inputs'!$G$3:$G$14,MATCH(1,'User Inputs'!$J$3:$J$14,0)) -> 2026M05 | H68: Periodic | I68: 611000 | J68: EndBal | K68: Top | L68: None | M68: 171 | N68: =_xlfn.CONCAT(C68,"_",M68) -> 111_171 | O68: Top | P68: 330180 | Q68: Top | R68: Top | S68: Top | T68: Top | U68: =_xll.OneStreamExcelAddIn.XFFunctions.XFGetCell(A68,B68,C68,D68,E68,F68,G68,H68,I68,J68,K68,L68,M68,N68,O68,P68,Q68,R68,S68,T68) -> 0
A69: TRUE | B69: finreporting | C69: 111 | E69: USD | F69: Actual | G69: =INDEX('User Inputs'!$G$3:$G$14,MATCH(1,'User Inputs'!$J$3:$J$14,0)) -> 2026M05 | H69: Periodic | I69: 611000 | J69: EndBal | K69: Top | L69: None | M69: 171 | N69: =_xlfn.CONCAT(C69,"_",M69) -> 111_171 | O69: Top | P69: 331200 | Q69: Top | R69: Top | S69: Top | T69: Top | U69: =_xll.OneStreamExcelAddIn.XFFunctions.XFGetCell(A69,B69,C69,D69,E69,F69,G69,H69,I69,J69,K69,L69,M69,N69,O69,P69,Q69,R69,S69,T69) -> 0
A70: TRUE | B70: finreporting | C70: 111 | E70: USD | F70: Actual | G70: =INDEX('User Inputs'!$G$3:$G$14,MATCH(1,'User Inputs'!$J$3:$J$14,0)) -> 2026M05 | H70: Periodic | I70: 611010 | J70: EndBal | K70: Top | L70: None | M70: 171 | N70: =_xlfn.CONCAT(C70,"_",M70) -> 111_171 | O70: Top | P70: 330210 | Q70: Top | R70: Top | S70: Top | T70: Top | U70: =_xll.OneStreamExcelAddIn.XFFunctions.XFGetCell(A70,B70,C70,D70,E70,F70,G70,H70,I70,J70,K70,L70,M70,N70,O70,P70,Q70,R70,S70,T70) -> 0
A71: TRUE | B71: finreporting | C71: 111 | E71: USD | F71: Actual | G71: =INDEX('User Inputs'!$G$3:$G$14,MATCH(1,'User Inputs'!$J$3:$J$14,0)) -> 2026M05 | H71: Periodic | I71: 611010 | J71: EndBal | K71: Top | L71: None | M71: 171 | N71: =_xlfn.CONCAT(C71,"_",M71) -> 111_171 | O71: Top | P71: 330200 | Q71: Top | R71: Top | S71: Top | T71: Top | U71: =_xll.OneStreamExcelAddIn.XFFunctions.XFGetCell(A71,B71,C71,D71,E71,F71,G71,H71,I71,J71,K71,L71,M71,N71,O71,P71,Q71,R71,S71,T71) -> 0
... A117: TRUE | B117: finreporting | C117: 111 | E117: USD | F117: Actual | G117: =INDEX('User Inputs'!$G$3:$G$14,MATCH(1,'User Inputs'!$J$3:$J$14,0)) -> 2026M05 | H117: Periodic | I117: 618350 | J117: EndBal | K117: Top | L117: None | M117: 171 | N117: =_xlfn.CONCAT(C117,"_",M117) -> 111_171 | O117: Top | P117: 331300 | Q117: Top | R117: Top | S117: Top | T117: Top | U117: =_xll.OneStreamExcelAddIn.XFFunctions.XFGetCell(A117,B117,C117,D117,E117,F117,G117,H117,I117,J117,K117,L117,M117,N117,O117,P117,Q117,R117,S117,T117) -> 0
A118: TRUE | B118: finreporting | C118: 111 | E118: USD | F118: Actual | G118: =INDEX('User Inputs'!$G$3:$G$14,MATCH(1,'User Inputs'!$J$3:$J$14,0)) -> 2026M05 | H118: Periodic | I118: 626088 | J118: EndBal | K118: Top | L118: None | M118: 171 | N118: =_xlfn.CONCAT(C118,"_",M118) -> 111_171 | O118: Top | P118: Top | Q118: Top | R118: Top | S118: Top | T118: Top | U118: =_xll.OneStreamExcelAddIn.XFFunctions.XFGetCell(A118,B118,C118,D118,E118,F118,G118,H118,I118,J118,K118,L118,M118,N118,O118,P118,Q118,R118,S118,T118) -> 0
A119: TRUE | B119: finreporting | C119: 111 | E119: USD | F119: Actual | G119: =INDEX('User Inputs'!$G$3:$G$14,MATCH(1,'User Inputs'!$J$3:$J$14,0)) -> 2026M05 | H119: Periodic | I119: 629999 | J119: EndBal | K119: Top | L119: None | M119: 171 | N119: =_xlfn.CONCAT(C119,"_",M119) -> 111_171 | O119: Top | P119: 331100 | Q119: Top | R119: Top | S119: Top | T119: Top | U119: =_xll.OneStreamExcelAddIn.XFFunctions.XFGetCell(A119,B119,C119,D119,E119,F119,G119,H119,I119,J119,K119,L119,M119,N119,O119,P119,Q119,R119,S119,T119) -> 0
A120: TRUE | B120: finreporting | C120: 213 | E120: USD | F120: Actual | G120: =INDEX('User Inputs'!$G$3:$G$14,MATCH(1,'User Inputs'!$J$3:$J$14,0)) -> 2026M05 | H120: Periodic | I120: 611000 | J120: EndBal | K120: Top | L120: None | M120: 170 | N120: =_xlfn.CONCAT(C120,"_",M120) -> 213_170 | O120: Top | P120: 330130 | Q120: Top | R120: Top | S120: Top | T120: Top | U120: =_xll.OneStreamExcelAddIn.XFFunctions.XFGetCell(A120,B120,C120,D120,E120,F120,G120,H120,I120,J120,K120,L120,M120,N120,O120,P120,Q120,R120,S120,T120) -> 0
A121: TRUE | B121: finreporting | C121: 213 | E121: USD | F121: Actual | G121: =INDEX('User Inputs'!$G$3:$G$14,MATCH(1,'User Inputs'!$J$3:$J$14,0)) -> 2026M05 | H121: Periodic | I121: 611000 | J121: EndBal | K121: Top | L121: None | M121: 170 | N121: =_xlfn.CONCAT(C121,"_",M121) -> 213_170 | O121: Top | P121: 330160 | Q121: Top | R121: Top | S121: Top | T121: Top | U121: =_xll.OneStreamExcelAddIn.XFFunctions.XFGetCell(A121,B121,C121,D121,E121,F121,G121,H121,I121,J121,K121,L121,M121,N121,O121,P121,Q121,R121,S121,T121) -> 0
A122: TRUE | B122: finreporting | C122: 213 | E122: USD | F122: Actual | G122: =INDEX('User Inputs'!$G$3:$G$14,MATCH(1,'User Inputs'!$J$3:$J$14,0)) -> 2026M05 | H122: Periodic | I122: 611000 | J122: EndBal | K122: Top | L122: None | M122: 170 | N122: =_xlfn.CONCAT(C122,"_",M122) -> 213_170 | O122: Top | P122: 330170 | Q122: Top | R122: Top | S122: Top | T122: Top | U122: =_xll.OneStreamExcelAddIn.XFFunctions.XFGetCell(A122,B122,C122,D122,E122,F122,G122,H122,I122,J122,K122,L122,M122,N122,O122,P122,Q122,R122,S122,T122) -> 0
A123: TRUE | B123: finreporting | C123: 213 | E123: USD | F123: Actual | G123: =INDEX('User Inputs'!$G$3:$G$14,MATCH(1,'User Inputs'!$J$3:$J$14,0)) -> 2026M05 | H123: Periodic | I123: 611000 | J123: EndBal | K123: Top | L123: None | M123: 170 | N123: =_xlfn.CONCAT(C123,"_",M123) -> 213_170 | O123: Top | P123: 330120 | Q123: Top | R123: Top | S123: Top | T123: Top | U123: =_xll.OneStreamExcelAddIn.XFFunctions.XFGetCell(A123,B123,C123,D123,E123,F123,G123,H123,I123,J123,K123,L123,M123,N123,O123,P123,Q123,R123,S123,T123) -> 0
A124: TRUE | B124: finreporting | C124: 213 | E124: USD | F124: Actual | G124: =INDEX('User Inputs'!$G$3:$G$14,MATCH(1,'User Inputs'!$J$3:$J$14,0)) -> 2026M05 | H124: Periodic | I124: 611000 | J124: EndBal | K124: Top | L124: None | M124: 170 | N124: =_xlfn.CONCAT(C124,"_",M124) -> 213_170 | O124: Top | P124: 330100 | Q124: Top | R124: Top | S124: Top | T124: Top | U124: =_xll.OneStreamExcelAddIn.XFFunctions.XFGetCell(A124,B124,C124,D124,E124,F124,G124,H124,I124,J124,K124,L124,M124,N124,O124,P124,Q124,R124,S124,T124) -> 0
A125: TRUE | B125: finreporting | C125: 213 | E125: USD | F125: Actual | G125: =INDEX('User Inputs'!$G$3:$G$14,MATCH(1,'User Inputs'!$J$3:$J$14,0)) -> 2026M05 | H125: Periodic | I125: 611000 | J125: EndBal | K125: Top | L125: None | M125: 170 | N125: =_xlfn.CONCAT(C125,"_",M125) -> 213_170 | O125: Top | P125: 330150 | Q125: Top | R125: Top | S125: Top | T125: Top | U125: =_xll.OneStreamExcelAddIn.XFFunctions.XFGetCell(A125,B125,C125,D125,E125,F125,G125,H125,I125,J125,K125,L125,M125,N125,O125,P125,Q125,R125,S125,T125) -> 0
A126: TRUE | B126: finreporting | C126: 213 | E126: USD | F126: Actual | G126: =INDEX('User Inputs'!$G$3:$G$14,MATCH(1,'User Inputs'!$J$3:$J$14,0)) -> 2026M05 | H126: Periodic | I126: 611000 | J126: EndBal | K126: Top | L126: None | M126: 170 | N126: =_xlfn.CONCAT(C126,"_",M126) -> 213_170 | O126: Top | P126: 330110 | Q126: Top | R126: Top | S126: Top | T126: Top | U126: =_xll.OneStreamExcelAddIn.XFFunctions.XFGetCell(A126,B126,C126,D126,E126,F126,G126,H126,I126,J126,K126,L126,M126,N126,O126,P126,Q126,R126,S126,T126) -> 0
A127: TRUE | B127: finreporting | C127: 213 | E127: USD | F127: Actual | G127: =INDEX('User Inputs'!$G$3:$G$14,MATCH(1,'User Inputs'!$J$3:$J$14,0)) -> 2026M05 | H127: Periodic | I127: 611000 | J127: EndBal | K127: Top | L127: None | M127: 170 | N127: =_xlfn.CONCAT(C127,"_",M127) -> 213_170 | O127: Top | P127: 330180 | Q127: Top | R127: Top | S127: Top | T127: Top | U127: =_xll.OneStreamExcelAddIn.XFFunctions.XFGetCell(A127,B127,C127,D127,E127,F127,G127,H127,I127,J127,K127,L127,M127,N127,O127,P127,Q127,R127,S127,T127) -> 0
A128: TRUE | B128: finreporting | C128: 213 | E128: USD | F128: Actual | G128: =INDEX('User Inputs'!$G$3:$G$14,MATCH(1,'User Inputs'!$J$3:$J$14,0)) -> 2026M05 | H128: Periodic | I128: 611000 | J128: EndBal | K128: Top | L128: None | M128: 170 | N128: =_xlfn.CONCAT(C128,"_",M128) -> 213_170 | O128: Top | P128: 331200 | Q128: Top | R128: Top | S128: Top | T128: Top | U128: =_xll.OneStreamExcelAddIn.XFFunctions.XFGetCell(A128,B128,C128,D128,E128,F128,G128,H128,I128,J128,K128,L128,M128,N128,O128,P128,Q128,R128,S128,T128) -> 0
A129: TRUE | B129: finreporting | C129: 213 | E129: USD | F129: Actual | G129: =INDEX('User Inputs'!$G$3:$G$14,MATCH(1,'User Inputs'!$J$3:$J$14,0)) -> 2026M05 | H129: Periodic | I129: 611010 | J129: EndBal | K129: Top | L129: None | M129: 170 | N129: =_xlfn.CONCAT(C129,"_",M129) -> 213_170 | O129: Top | P129: 330210 | Q129: Top | R129: Top | S129: Top | T129: Top | U129: =_xll.OneStreamExcelAddIn.XFFunctions.XFGetCell(A129,B129,C129,D129,E129,F129,G129,H129,I129,J129,K129,L129,M129,N129,O129,P129,Q129,R129,S129,T129) -> 0
...

Sheet Formatted
A1: String code | B1: Company | C1: Department | D1: Account | E1: Activity | F1: Month | G1: Year | H1: Spend | J1: =SUM(H2:H237) -> 5975314.3
A2: =_xlfn.CONCAT(B2,"-",C2,D2,E2) -> 111-170611000330130 | B2: ='OneStream Pulls'!C2 -> 111 | C2: ='OneStream Pulls'!M2 -> 170 | D2: ='OneStream Pulls'!I2 -> 611000 | E2: =IF(ISNUMBER('OneStream Pulls'!P2),'OneStream Pulls'!P2,0) -> 330130 | F2: =INDEX('User Inputs'!$I$3:$I$14,MATCH('OneStream Pulls'!G2,'User Inputs'!$G$3:$G$14,0)) -> May | G2: =LEFT('OneStream Pulls'!G2,4) -> 2026 | H2: ='OneStream Pulls'!U2 -> 0
A3: =_xlfn.CONCAT(B3,"-",C3,D3,E3) -> 111-170611000330160 | B3: ='OneStream Pulls'!C3 -> 111 | C3: ='OneStream Pulls'!M3 -> 170 | D3: ='OneStream Pulls'!I3 -> 611000 | E3: =IF(ISNUMBER('OneStream Pulls'!P3),'OneStream Pulls'!P3,0) -> 330160 | F3: =INDEX('User Inputs'!$I$3:$I$14,MATCH('OneStream Pulls'!G3,'User Inputs'!$G$3:$G$14,0)) -> May | G3: =LEFT('OneStream Pulls'!G3,4) -> 2026 | H3: ='OneStream Pulls'!U3 -> 0
A4: =_xlfn.CONCAT(B4,"-",C4,D4,E4) -> 111-170611000330170 | B4: ='OneStream Pulls'!C4 -> 111 | C4: ='OneStream Pulls'!M4 -> 170 | D4: ='OneStream Pulls'!I4 -> 611000 | E4: =IF(ISNUMBER('OneStream Pulls'!P4),'OneStream Pulls'!P4,0) -> 330170 | F4: =INDEX('User Inputs'!$I$3:$I$14,MATCH('OneStream Pulls'!G4,'User Inputs'!$G$3:$G$14,0)) -> May | G4: =LEFT('OneStream Pulls'!G4,4) -> 2026 | H4: ='OneStream Pulls'!U4 -> 0
A5: =_xlfn.CONCAT(B5,"-",C5,D5,E5) -> 111-170611000330120 | B5: ='OneStream Pulls'!C5 -> 111 | C5: ='OneStream Pulls'!M5 -> 170 | D5: ='OneStream Pulls'!I5 -> 611000 | E5: =IF(ISNUMBER('OneStream Pulls'!P5),'OneStream Pulls'!P5,0) -> 330120 | F5: =INDEX('User Inputs'!$I$3:$I$14,MATCH('OneStream Pulls'!G5,'User Inputs'!$G$3:$G$14,0)) -> May | G5: =LEFT('OneStream Pulls'!G5,4) -> 2026 | H5: ='OneStream Pulls'!U5 -> 0
A6: =_xlfn.CONCAT(B6,"-",C6,D6,E6) -> 111-170611000330100 | B6: ='OneStream Pulls'!C6 -> 111 | C6: ='OneStream Pulls'!M6 -> 170 | D6: ='OneStream Pulls'!I6 -> 611000 | E6: =IF(ISNUMBER('OneStream Pulls'!P6),'OneStream Pulls'!P6,0) -> 330100 | F6: =INDEX('User Inputs'!$I$3:$I$14,MATCH('OneStream Pulls'!G6,'User Inputs'!$G$3:$G$14,0)) -> May | G6: =LEFT('OneStream Pulls'!G6,4) -> 2026 | H6: ='OneStream Pulls'!U6 -> 306779.49
A7: =_xlfn.CONCAT(B7,"-",C7,D7,E7) -> 111-170611000330150 | B7: ='OneStream Pulls'!C7 -> 111 | C7: ='OneStream Pulls'!M7 -> 170 | D7: ='OneStream Pulls'!I7 -> 611000 | E7: =IF(ISNUMBER('OneStream Pulls'!P7),'OneStream Pulls'!P7,0) -> 330150 | F7: =INDEX('User Inputs'!$I$3:$I$14,MATCH('OneStream Pulls'!G7,'User Inputs'!$G$3:$G$14,0)) -> May | G7: =LEFT('OneStream Pulls'!G7,4) -> 2026 | H7: ='OneStream Pulls'!U7 -> 0
A8: =_xlfn.CONCAT(B8,"-",C8,D8,E8) -> 111-170611000330110 | B8: ='OneStream Pulls'!C8 -> 111 | C8: ='OneStream Pulls'!M8 -> 170 | D8: ='OneStream Pulls'!I8 -> 611000 | E8: =IF(ISNUMBER('OneStream Pulls'!P8),'OneStream Pulls'!P8,0) -> 330110 | F8: =INDEX('User Inputs'!$I$3:$I$14,MATCH('OneStream Pulls'!G8,'User Inputs'!$G$3:$G$14,0)) -> May | G8: =LEFT('OneStream Pulls'!G8,4) -> 2026 | H8: ='OneStream Pulls'!U8 -> 0
A9: =_xlfn.CONCAT(B9,"-",C9,D9,E9) -> 111-170611000330180 | B9: ='OneStream Pulls'!C9 -> 111 | C9: ='OneStream Pulls'!M9 -> 170 | D9: ='OneStream Pulls'!I9 -> 611000 | E9: =IF(ISNUMBER('OneStream Pulls'!P9),'OneStream Pulls'!P9,0) -> 330180 | F9: =INDEX('User Inputs'!$I$3:$I$14,MATCH('OneStream Pulls'!G9,'User Inputs'!$G$3:$G$14,0)) -> May | G9: =LEFT('OneStream Pulls'!G9,4) -> 2026 | H9: ='OneStream Pulls'!U9 -> 0
A10: =_xlfn.CONCAT(B10,"-",C10,D10,E10) -> 111-170611000331200 | B10: ='OneStream Pulls'!C10 -> 111 | C10: ='OneStream Pulls'!M10 -> 170 | D10: ='OneStream Pulls'!I10 -> 611000 | E10: =IF(ISNUMBER('OneStream Pulls'!P10),'OneStream Pulls'!P10,0) -> 331200 | F10: =INDEX('User Inputs'!$I$3:$I$14,MATCH('OneStream Pulls'!G10,'User Inputs'!$G$3:$G$14,0)) -> May | G10: =LEFT('OneStream Pulls'!G10,4) -> 2026 | H10: ='OneStream Pulls'!U10 -> 35500
A11: =_xlfn.CONCAT(B11,"-",C11,D11,E11) -> 111-170611010330210 | B11: ='OneStream Pulls'!C11 -> 111 | C11: ='OneStream Pulls'!M11 -> 170 | D11: ='OneStream Pulls'!I11 -> 611010 | E11: =IF(ISNUMBER('OneStream Pulls'!P11),'OneStream Pulls'!P11,0) -> 330210 | F11: =INDEX('User Inputs'!$I$3:$I$14,MATCH('OneStream Pulls'!G11,'User Inputs'!$G$3:$G$14,0)) -> May | G11: =LEFT('OneStream Pulls'!G11,4) -> 2026 | H11: ='OneStream Pulls'!U11 -> 0
A12: =_xlfn.CONCAT(B12,"-",C12,D12,E12) -> 111-170611010330200 | B12: ='OneStream Pulls'!C12 -> 111 | C12: ='OneStream Pulls'!M12 -> 170 | D12: ='OneStream Pulls'!I12 -> 611010 | E12: =IF(ISNUMBER('OneStream Pulls'!P12),'OneStream Pulls'!P12,0) -> 330200 | F12: =INDEX('User Inputs'!$I$3:$I$14,MATCH('OneStream Pulls'!G12,'User Inputs'!$G$3:$G$14,0)) -> May | G12: =LEFT('OneStream Pulls'!G12,4) -> 2026 | H12: ='OneStream Pulls'!U12 -> 7977
A13: =_xlfn.CONCAT(B13,"-",C13,D13,E13) -> 111-170611010330220 | B13: ='OneStream Pulls'!C13 -> 111 | C13: ='OneStream Pulls'!M13 -> 170 | D13: ='OneStream Pulls'!I13 -> 611010 | E13: =IF(ISNUMBER('OneStream Pulls'!P13),'OneStream Pulls'!P13,0) -> 330220 | F13: =INDEX('User Inputs'!$I$3:$I$14,MATCH('OneStream Pulls'!G13,'User Inputs'!$G$3:$G$14,0)) -> May | G13: =LEFT('OneStream Pulls'!G13,4) -> 2026 | H13: ='OneStream Pulls'!U13 -> 0
... A237: =_xlfn.CONCAT(B237,"-",C237,D237,E237) -> 111-172629999331100 | B237: ='OneStream Pulls'!C237 -> 111 | C237: ='OneStream Pulls'!M237 -> 172 | D237: ='OneStream Pulls'!I237 -> 629999 | E237: =IF(ISNUMBER('OneStream Pulls'!P237),'OneStream Pulls'!P237,0) -> 331100 | F237: =INDEX('User Inputs'!$I$3:$I$14,MATCH('OneStream Pulls'!G237,'User Inputs'!$G$3:$G$14,0)) -> May | G237: =LEFT('OneStream Pulls'!G237,4) -> 2026 | H237: ='OneStream Pulls'!U237 -> 0
A238: =_xlfn.CONCAT(B238,"-",C238,D238,E238) -> 111-170SACADV0 | B238: 111 | C238: 170 | D238: SACADV | E238: 0 | F238: =INDEX('User Inputs'!$I$3:$I$14,MATCH('OneStream Pulls'!G238,'User Inputs'!$G$3:$G$14,0)) -> May | G238: =LEFT('OneStream Pulls'!G238,4) -> 2026 | H238: =SUM('OneStream Pulls'!U238:U262) -> 378772.66
A239: =_xlfn.CONCAT(B239,"-",C239,D239,E239) -> 111-170SACADV2 | B239: 111 | C239: 170 | D239: SACADV | E239: 2 | F239: =INDEX('User Inputs'!$I$3:$I$14,MATCH('OneStream Pulls'!G239,'User Inputs'!$G$3:$G$14,0)) -> May | G239: =LEFT('OneStream Pulls'!G239,4) -> 2026 | H239: =SUM('OneStream Pulls'!U263:U270) -> 0
A240: =_xlfn.CONCAT(B240,"-",C240,D240,E240) -> 111-170SACADV1 | B240: 111 | C240: 170 | D240: SACADV | E240: 1 | F240: =INDEX('User Inputs'!$I$3:$I$14,MATCH('OneStream Pulls'!G240,'User Inputs'!$G$3:$G$14,0)) -> May | G240: =LEFT('OneStream Pulls'!G240,4) -> 2026 | H240: =SUM('OneStream Pulls'!U271:U299) -> 5142.28
